import { AppError } from "../../../../shared/errors/AppError";
import { CategoriesRepositoryInMemory } from "../../repositories/in-memory/CategoriesRepositoryInMemory";
import { CreateCategoryUseCase } from "./CreateCategoryUseCase";

let createCategoryUseCase: CreateCategoryUseCase;
let categoriesRepositoryInMemory: CategoriesRepositoryInMemory;

describe("Create category", () => {
  beforeEach(() => {
    categoriesRepositoryInMemory = new CategoriesRepositoryInMemory();
    createCategoryUseCase = new CreateCategoryUseCase(
      categoriesRepositoryInMemory
    );
  });

  it("should be able to create a category", async () => {
    const category = {
      name: "category test",
      description: "category description test",
    };
    await createCategoryUseCase.execute({
      name: category.name,
      description: category.description,
    });
    const categoryCreated = await categoriesRepositoryInMemory.findByName(
      category.name
    );
    expect(categoryCreated).toHaveProperty("id");
  });

  it("should not be able to create if already exists", async () => {
    expect(async () => {
      const category = {
        name: "category test",
        description: "category description test",
      };
      //Chamar 2x pois da segunda vai dar erro pq o nome foi repetido
      await createCategoryUseCase.execute({
        name: category.name,
        description: category.description,
      });
      await createCategoryUseCase.execute({
        name: category.name,
        description: category.description,
      });
    }).rejects.toBeInstanceOf(AppError);
  });
});
